#VRML_SIM R2025a utf8

EXTERNPROTO "https://raw.githubusercontent.com/cyberbotics/webots/R2025a/projects/objects/backgrounds/protos/TexturedBackground.proto"
EXTERNPROTO "https://raw.githubusercontent.com/cyberbotics/webots/R2025a/projects/objects/backgrounds/protos/TexturedBackgroundLight.proto"
EXTERNPROTO "https://raw.githubusercontent.com/cyberbotics/webots/R2025a/projects/objects/floors/protos/RectangleArena.proto"
EXTERNPROTO "https://raw.githubusercontent.com/cyberbotics/webots/R2025a/projects/humans/pedestrian/protos/Pedestrian.proto"
EXTERNPROTO "https://raw.githubusercontent.com/cyberbotics/webots/R2025a/projects/objects/tables/protos/Table.proto"
EXTERNPROTO "https://raw.githubusercontent.com/cyberbotics/webots/R2025a/projects/objects/factory/forklift/protos/Forklift.proto"
EXTERNPROTO "https://raw.githubusercontent.com/cyberbotics/webots/R2025a/projects/objects/factory/containers/protos/CardboardBox.proto"
EXTERNPROTO "https://raw.githubusercontent.com/cyberbotics/webots/R2025a/projects/objects/factory/pallet/protos/WoodenPallet.proto"
EXTERNPROTO "https://raw.githubusercontent.com/cyberbotics/webots/R2025a/projects/appearances/protos/DryMud.proto"

WorldInfo {
}
Viewpoint {
  orientation -0.0426734182830229 0.04548957692946039 -0.9980529433666437 4.774437066389984
  position 0.07263873751374561 -4.485042788793504 0.5420286631093186
}
TexturedBackground {
}
TexturedBackgroundLight {
}
RectangleArena {
  floorSize 20 20
  floorAppearance DryMud {
  }
}
Table {
  translation -7.2 -6.5 0
  rotation 0 1 0 4.692820414042842e-06
}
Pedestrian {
  translation 1.94 2.77 1.27
}
Robot {
  rotation 0 0 1 3.14
  children [
    DEF Body Pose {
      translation 0 0 0.315
      children [
        Shape {
          appearance PBRAppearance {
            baseColor 0 0 1
            metalness 0
          }
          geometry Cylinder {
            height 0.6
            radius 0.3
          }
        }
      ]
    }
    HingeJoint {
      jointParameters HingeJointParameters {
        anchor 0.3 0 0.167
      }
      device [
        RotationalMotor {
          name "motor_1"
        }
      ]
      endPoint Solid {
        translation 0.3 0 0.167
        rotation 0 1 0 1.57
        children [
          DEF Wheel Shape {
            appearance PBRAppearance {
              baseColor 1 0 0
              roughness 1
              metalness 0
            }
            geometry Cylinder {
              height 0.1
              radius 0.167
            }
          }
        ]
        boundingObject USE Wheel
        physics DEF wheel_Physics Physics {
        }
      }
    }
    HingeJoint {
      jointParameters HingeJointParameters {
        anchor -0.3 0 0.167
      }
      device [
        RotationalMotor {
          name "motor_2"
        }
      ]
      endPoint Solid {
        translation -0.3 0 0.167
        rotation 0 1 0 1.57
        children [
          USE Wheel
        ]
        name "solid(1)"
        boundingObject USE Wheel
        physics USE wheel_Physics
      }
    }
    Solid {
      translation -0.13 0.26 0.5
      children [
        DEF eye Shape {
          appearance PBRAppearance {
            baseColor 1 0 0
            roughness 1
            metalness 0
          }
          geometry Box {
            size 0.04 0.05 0.05
          }
        }
      ]
      name "solid(2)"
    }
    Solid {
      translation 0.13 0.26 0.5
      children [
        USE eye
      ]
      name "solid(3)"
    }
  ]
  boundingObject USE Body
}
Solid {
  translation -2.52 0 0.23
  children [
    DEF G0 Group {
      children [
        Forklift {
          translation 0 0.01254980355525507 0.33997186429150095
        }
        Pedestrian {
          translation 0 0 0.87
        }
      ]
    }
  ]
}
CardboardBox {
  translation 4.3 0 0.3
}
WoodenPallet {
  translation 0 2.54 0
}
